package cn.alan.exception;

public class FinallyTest {
    public static void main(String[] args) {
        System.out.println(getInt());
    }

    public static int getInt() {
        int a = 10;
        try {
            System.out.println(a / 0);
            a = 20;
        } catch (ArithmeticException e) {
            a = 30;
            return a;
            /*
             * return a 在程序执行到这一步的时候，这里不是return a 而是 return 30；
             * 但是呢，它发现后面还有finally，所以继续执行finally的内容，a=40
             * 再次回到以前的路径,继续走return 30，形成返回路径之后，这里的a就不是a变
             */
        } finally {
            a = 40;
            // 如果下面这样写，执行结果就是 40
            return a;
        }
        // return a;
    }
}
